2019-05-08 20:04:17,664	INFO node.py:469 -- Process STDOUT and STDERR is being redirected to /tmp/ray/session_2019-05-08_20-04-17_5697/logs.
2019-05-08 20:04:17,770	INFO services.py:407 -- Waiting for redis server at 127.0.0.1:40475 to respond...
2019-05-08 20:04:17,877	INFO services.py:407 -- Waiting for redis server at 127.0.0.1:52007 to respond...
2019-05-08 20:04:17,878	INFO services.py:804 -- Starting Redis shard with 10.0 GB max memory.
2019-05-08 20:04:17,884	INFO node.py:483 -- Process STDOUT and STDERR is being redirected to /tmp/ray/session_2019-05-08_20-04-17_5697/logs.
2019-05-08 20:04:17,884	WARNING services.py:1304 -- WARNING: The object store is using /tmp instead of /dev/shm because /dev/shm has only 33710485504 bytes available. This may slow down performance! You may be able to free up space by deleting files in /dev/shm or terminating any running plasma_store_server processes. If you are inside a Docker container, you may need to pass an argument with the flag '--shm-size' to 'docker run'.
2019-05-08 20:04:17,884	INFO services.py:1427 -- Starting the Plasma object store with 40.0 GB memory using /tmp.
  0%|          | 0/1000 [00:00<?, ?it/s]
Traceback (most recent call last):
  File "log_clean.py", line 40, in <module>
    df = df.apply(invalid_date, axis=1)
  File "/home/lab/Softwares/miniconda3/envs/fastai/lib/python3.6/site-packages/pandas/core/frame.py", line 6487, in apply
    return op.get_result()
  File "/home/lab/Softwares/miniconda3/envs/fastai/lib/python3.6/site-packages/pandas/core/apply.py", line 151, in get_result
    return self.apply_standard()
  File "/home/lab/Softwares/miniconda3/envs/fastai/lib/python3.6/site-packages/pandas/core/apply.py", line 257, in apply_standard
    self.apply_series_generator()
  File "/home/lab/Softwares/miniconda3/envs/fastai/lib/python3.6/site-packages/pandas/core/apply.py", line 285, in apply_series_generator
    for i, v in enumerate(series_gen):
  File "/home/lab/Softwares/miniconda3/envs/fastai/lib/python3.6/site-packages/pandas/core/apply.py", line 367, in <genexpr>
    for i, (arr, name) in enumerate(zip(self.values,
  File "/home/lab/Softwares/miniconda3/envs/fastai/lib/python3.6/site-packages/pandas/core/series.py", line 262, in __init__
    raise_cast_failure=True)
  File "/home/lab/Softwares/miniconda3/envs/fastai/lib/python3.6/site-packages/pandas/core/internals/construction.py", line 673, in sanitize_array
    if is_object_dtype(subarr.dtype) and dtype != 'object':
  File "/home/lab/Softwares/miniconda3/envs/fastai/lib/python3.6/site-packages/pandas/core/dtypes/common.py", line 157, in is_object_dtype
    return _is_dtype_type(arr_or_dtype, classes(np.object_))
KeyboardInterrupt
Exception in thread ray_listen_error_messages:
Traceback (most recent call last):
  File "/home/lab/Softwares/miniconda3/envs/fastai/lib/python3.6/site-packages/redis/connection.py", line 185, in _read_from_socket
    raise socket.error(SERVER_CLOSED_CONNECTION_ERROR)
OSError: Connection closed by server.

During handling of the above exception, another exception occurred:

Traceback (most recent call last):
  File "/home/lab/Softwares/miniconda3/envs/fastai/lib/python3.6/threading.py", line 916, in _bootstrap_inner
    self.run()
  File "/home/lab/Softwares/miniconda3/envs/fastai/lib/python3.6/threading.py", line 864, in run
    self._target(*self._args, **self._kwargs)
  File "/home/lab/Softwares/miniconda3/envs/fastai/lib/python3.6/site-packages/ray/worker.py", line 1650, in listen_error_messages_raylet
    msg = worker.error_message_pubsub_client.get_message()
  File "/home/lab/Softwares/miniconda3/envs/fastai/lib/python3.6/site-packages/redis/client.py", line 3135, in get_message
    response = self.parse_response(block=False, timeout=timeout)
  File "/home/lab/Softwares/miniconda3/envs/fastai/lib/python3.6/site-packages/redis/client.py", line 3036, in parse_response
    return self._execute(connection, connection.read_response)
  File "/home/lab/Softwares/miniconda3/envs/fastai/lib/python3.6/site-packages/redis/client.py", line 3013, in _execute
    return command(*args)
  File "/home/lab/Softwares/miniconda3/envs/fastai/lib/python3.6/site-packages/redis/connection.py", line 637, in read_response
    response = self._parser.read_response()
  File "/home/lab/Softwares/miniconda3/envs/fastai/lib/python3.6/site-packages/redis/connection.py", line 290, in read_response
    response = self._buffer.readline()
  File "/home/lab/Softwares/miniconda3/envs/fastai/lib/python3.6/site-packages/redis/connection.py", line 224, in readline
    self._read_from_socket()
  File "/home/lab/Softwares/miniconda3/envs/fastai/lib/python3.6/site-packages/redis/connection.py", line 199, in _read_from_socket
    (e.args,))
redis.exceptions.ConnectionError: Error while reading from socket: ('Connection closed by server.',)

Exception in thread ray_print_logs:
Traceback (most recent call last):
  File "/home/lab/Softwares/miniconda3/envs/fastai/lib/python3.6/site-packages/redis/connection.py", line 185, in _read_from_socket
    raise socket.error(SERVER_CLOSED_CONNECTION_ERROR)
OSError: Connection closed by server.

During handling of the above exception, another exception occurred:

Traceback (most recent call last):
  File "/home/lab/Softwares/miniconda3/envs/fastai/lib/python3.6/threading.py", line 916, in _bootstrap_inner
    self.run()
  File "/home/lab/Softwares/miniconda3/envs/fastai/lib/python3.6/threading.py", line 864, in run
    self._target(*self._args, **self._kwargs)
  File "/home/lab/Softwares/miniconda3/envs/fastai/lib/python3.6/site-packages/ray/worker.py", line 1547, in print_logs
    msg = pubsub_client.get_message()
  File "/home/lab/Softwares/miniconda3/envs/fastai/lib/python3.6/site-packages/redis/client.py", line 3135, in get_message
    response = self.parse_response(block=False, timeout=timeout)
  File "/home/lab/Softwares/miniconda3/envs/fastai/lib/python3.6/site-packages/redis/client.py", line 3036, in parse_response
    return self._execute(connection, connection.read_response)
  File "/home/lab/Softwares/miniconda3/envs/fastai/lib/python3.6/site-packages/redis/client.py", line 3013, in _execute
    return command(*args)
  File "/home/lab/Softwares/miniconda3/envs/fastai/lib/python3.6/site-packages/redis/connection.py", line 637, in read_response
    response = self._parser.read_response()
  File "/home/lab/Softwares/miniconda3/envs/fastai/lib/python3.6/site-packages/redis/connection.py", line 290, in read_response
    response = self._buffer.readline()
  File "/home/lab/Softwares/miniconda3/envs/fastai/lib/python3.6/site-packages/redis/connection.py", line 224, in readline
    self._read_from_socket()
  File "/home/lab/Softwares/miniconda3/envs/fastai/lib/python3.6/site-packages/redis/connection.py", line 199, in _read_from_socket
    (e.args,))
redis.exceptions.ConnectionError: Error while reading from socket: ('Connection closed by server.',)

Exception in thread ray_import_thread:
Traceback (most recent call last):
  File "/home/lab/Softwares/miniconda3/envs/fastai/lib/python3.6/site-packages/redis/connection.py", line 185, in _read_from_socket
    raise socket.error(SERVER_CLOSED_CONNECTION_ERROR)
OSError: Connection closed by server.

During handling of the above exception, another exception occurred:

Traceback (most recent call last):
  File "/home/lab/Softwares/miniconda3/envs/fastai/lib/python3.6/threading.py", line 916, in _bootstrap_inner
    self.run()
  File "/home/lab/Softwares/miniconda3/envs/fastai/lib/python3.6/threading.py", line 864, in run
    self._target(*self._args, **self._kwargs)
  File "/home/lab/Softwares/miniconda3/envs/fastai/lib/python3.6/site-packages/ray/import_thread.py", line 70, in _run
    msg = import_pubsub_client.get_message()
  File "/home/lab/Softwares/miniconda3/envs/fastai/lib/python3.6/site-packages/redis/client.py", line 3135, in get_message
    response = self.parse_response(block=False, timeout=timeout)
  File "/home/lab/Softwares/miniconda3/envs/fastai/lib/python3.6/site-packages/redis/client.py", line 3036, in parse_response
    return self._execute(connection, connection.read_response)
  File "/home/lab/Softwares/miniconda3/envs/fastai/lib/python3.6/site-packages/redis/client.py", line 3013, in _execute
    return command(*args)
  File "/home/lab/Softwares/miniconda3/envs/fastai/lib/python3.6/site-packages/redis/connection.py", line 637, in read_response
    response = self._parser.read_response()
  File "/home/lab/Softwares/miniconda3/envs/fastai/lib/python3.6/site-packages/redis/connection.py", line 290, in read_response
    response = self._buffer.readline()
  File "/home/lab/Softwares/miniconda3/envs/fastai/lib/python3.6/site-packages/redis/connection.py", line 224, in readline
    self._read_from_socket()
  File "/home/lab/Softwares/miniconda3/envs/fastai/lib/python3.6/site-packages/redis/connection.py", line 199, in _read_from_socket
    (e.args,))
redis.exceptions.ConnectionError: Error while reading from socket: ('Connection closed by server.',)

